{
    "assignee": null,
    "assignees": [],
    "author_association": "NONE",
    "body": "Hi.\r\nWell, basicly i want to decode a bytes variable into an unicode one, like `uni = by.decode(\"utf-16\")`. That works on non-compiled python, but  crashes with .pyd files. But only in python3. If i compile my code and run it in py2, it works as it should.\r\n\r\nAlso gcc give me this warnings when compile my code for py3 (but they don't appear when compiling for python2):\r\n\r\n```\r\nsrc\\packages\\StatChars.c: In function '__pyx_pf_8packages_9StatChars_9StatChars___init__':\r\nsrc\\packages\\StatChars.c:1390:87: warning: passing argument 6 of '__Pyx_decode_bytes' from incompatible pointer type [-Wincompatible-pointer-types]\r\n     __pyx_t_1 = __Pyx_decode_bytes(__pyx_v_self->type, 0, PY_SSIZE_T_MAX, NULL, NULL, PyUnicode_DecodeUTF16); if (unlikely(!__pyx_t_1)) __PYX_ERR(0, 21, __pyx_L1_error)\r\n                                                                                       ^\r\nsrc\\packages\\StatChars.c:857:32: note: expected 'PyObject * (*)(const char *, Py_ssize_t,  const char *) {aka struct _object * (*)(const char *, int,  const char *)}' but argument is of type 'PyObject * (*)(const char *, Py_ssize_t,  const char *, int *) {aka struct _object * (*)(const char *, int,  const char *, int *)}'\r\n static CYTHON_INLINE PyObject* __Pyx_decode_bytes(\r\n                                ^\r\nsrc\\packages\\StatChars.c:1419:91: warning: passing argument 6 of '__Pyx_decode_bytes' from incompatible pointer type [-Wincompatible-pointer-types]\r\n     __pyx_t_1 = __Pyx_decode_bytes(__pyx_v_self->textType, 0, PY_SSIZE_T_MAX, NULL, NULL, PyUnicode_DecodeUTF16); if (unlikely(!__pyx_t_1)) __PYX_ERR(0, 22, __pyx_L1_error)\r\n                                                                                           ^\r\nsrc\\packages\\StatChars.c:857:32: note: expected 'PyObject * (*)(const char *, Py_ssize_t,  const char *) {aka struct _object * (*)(const char *, int,  const char *)}' but argument is of type 'PyObject * (*)(const char *, Py_ssize_t,  const char *, int *) {aka struct _object * (*)(const char *, int,  const char *, int *)}'\r\n static CYTHON_INLINE PyObject* __Pyx_decode_bytes(\r\n                                ^\r\nsrc\\packages\\StatChars.c:1457:89: warning: passing argument 6 of '__Pyx_decode_bytes' from incompatible pointer type [-Wincompatible-pointer-types]\r\n       __pyx_t_1 = __Pyx_decode_bytes(__pyx_v_self->text, 0, PY_SSIZE_T_MAX, NULL, NULL, PyUnicode_DecodeUTF16); if (unlikely(!__pyx_t_1)) __PYX_ERR(0, 24, __pyx_L6_error)\r\n                                                                                         ^\r\nsrc\\packages\\StatChars.c:857:32: note: expected 'PyObject * (*)(const char *, Py_ssize_t,  const char *) {aka struct _object * (*)(const char *, int,  const char *)}' but argument is of type 'PyObject * (*)(const char *, Py_ssize_t,  const char *, int *) {aka struct _object * (*)(const char *, int,  const char *, int *)}'\r\n static CYTHON_INLINE PyObject* __Pyx_decode_bytes(\r\n                                ^\r\nsrc\\packages\\StatChars.c: In function '__pyx_f_8packages_9StatChars_9StatChars_getUnicodeList':\r\nsrc\\packages\\StatChars.c:1693:85: warning: passing argument 6 of '__Pyx_decode_bytes' from incompatible pointer type [-Wincompatible-pointer-types]\r\n   __pyx_t_1 = __Pyx_decode_bytes(__pyx_v_self->type, 0, PY_SSIZE_T_MAX, NULL, NULL, PyUnicode_DecodeUTF16); if (unlikely(!__pyx_t_1)) __PYX_ERR(0, 31, __pyx_L1_error)\r\n                                                                                     ^\r\nsrc\\packages\\StatChars.c:857:32: note: expected 'PyObject * (*)(const char *, Py_ssize_t,  const char *) {aka struct _object * (*)(const char *, int,  const char *)}' but argument is of type 'PyObject * (*)(const char *, Py_ssize_t,  const char *, int *) {aka struct _object * (*)(const char *, int,  const char *, int *)}'\r\n static CYTHON_INLINE PyObject* __Pyx_decode_bytes(\r\n                                ^\r\nsrc\\packages\\StatChars.c:1726:78: warning: passing argument 6 of '__Pyx_decode_bytes' from incompatible pointer type [-Wincompatible-pointer-types]\r\n     __pyx_t_1 = __Pyx_decode_bytes(__pyx_t_2, 0, PY_SSIZE_T_MAX, NULL, NULL, PyUnicode_DecodeUTF16); if (unlikely(!__pyx_t_1)) __PYX_ERR(0, 33, __pyx_L1_error)\r\n                                                                              ^\r\nsrc\\packages\\StatChars.c:857:32: note: expected 'PyObject * (*)(const char *, Py_ssize_t,  const char *) {aka struct _object * (*)(const char *, int,  const char *)}' but argument is of type 'PyObject * (*)(const char *, Py_ssize_t,  const char *, int *) {aka struct _object * (*)(const char *, int,  const char *, int *)}'\r\n static CYTHON_INLINE PyObject* __Pyx_decode_bytes(\r\n                                ^\r\nsrc\\packages\\StatChars.c:1754:87: warning: passing argument 6 of '__Pyx_decode_bytes' from incompatible pointer type [-Wincompatible-pointer-types]\r\n     __pyx_t_1 = __Pyx_decode_bytes(__pyx_v_self->text, 0, PY_SSIZE_T_MAX, NULL, NULL, PyUnicode_DecodeUTF16); if (unlikely(!__pyx_t_1)) __PYX_ERR(0, 35, __pyx_L1_error)\r\n                                                                                       ^\r\nsrc\\packages\\StatChars.c:857:32: note: expected 'PyObject * (*)(const char *, Py_ssize_t,  const char *) {aka struct _object * (*)(const char *, int,  const char *)}' but argument is of type 'PyObject * (*)(const char *, Py_ssize_t,  const char *, int *) {aka struct _object * (*)(const char *, int,  const char *, int *)}'\r\n static CYTHON_INLINE PyObject* __Pyx_decode_bytes(\r\n```",
    "closed_at": null,
    "comment_data": [
        {
            "author_association": "OWNER",
            "body": "Are you using Cython 0.27.1?\n",
            "created_at": "2017-10-10T04:51:22Z",
            "html_url": "https://github.com/cython/cython/issues/1922#issuecomment-335360254",
            "id": 335360254,
            "issue_url": "https://api.github.com/repos/cython/cython/issues/1922",
            "updated_at": "2017-10-10T04:51:22Z",
            "url": "https://api.github.com/repos/cython/cython/issues/comments/335360254",
            "user": {
                "avatar_url": "https://avatars0.githubusercontent.com/u/491659?v=4",
                "events_url": "https://api.github.com/users/scoder/events{/privacy}",
                "followers_url": "https://api.github.com/users/scoder/followers",
                "following_url": "https://api.github.com/users/scoder/following{/other_user}",
                "gists_url": "https://api.github.com/users/scoder/gists{/gist_id}",
                "gravatar_id": "",
                "html_url": "https://github.com/scoder",
                "id": 491659,
                "login": "scoder",
                "organizations_url": "https://api.github.com/users/scoder/orgs",
                "received_events_url": "https://api.github.com/users/scoder/received_events",
                "repos_url": "https://api.github.com/users/scoder/repos",
                "site_admin": false,
                "starred_url": "https://api.github.com/users/scoder/starred{/owner}{/repo}",
                "subscriptions_url": "https://api.github.com/users/scoder/subscriptions",
                "type": "User",
                "url": "https://api.github.com/users/scoder"
            }
        },
        {
            "author_association": "NONE",
            "body": "Well, this is embarrassing...\r\nI updated cython and now this doesn't make trouble. c: Thanks a lot, i don't know how i didn't tried that.\r\n\r\n\r\nOther problem i have with cython (i think i should ask this on another issue...), is always getting this warnings when compiling for py3 (they don't appear when compiling for py2):\r\n\r\n```\r\nIn file included from C:\\Program Files (x86)\\Python36-32\\include/Python.h:65:0,\r\n                 from src\\main.c:4:\r\nC:\\Program Files (x86)\\Python36-32\\include/pytime.h:112:5: warning: 'struct timeval' declared inside parameter list\r\n     _PyTime_round_t round);\r\n     ^\r\nC:\\Program Files (x86)\\Python36-32\\include/pytime.h:112:5: warning: its scope is only this definition or declaration, which is probably not what you want\r\nC:\\Program Files (x86)\\Python36-32\\include/pytime.h:117:5: warning: 'struct timeval' declared inside parameter list\r\n     _PyTime_round_t round);\r\n     ^\r\n```\r\n\r\nalthough they appear, it seems to not be affecting in any way.",
            "created_at": "2017-10-10T14:14:38Z",
            "html_url": "https://github.com/cython/cython/issues/1922#issuecomment-335486485",
            "id": 335486485,
            "issue_url": "https://api.github.com/repos/cython/cython/issues/1922",
            "updated_at": "2017-10-10T14:14:38Z",
            "url": "https://api.github.com/repos/cython/cython/issues/comments/335486485",
            "user": {
                "avatar_url": "https://avatars2.githubusercontent.com/u/7416381?v=4",
                "events_url": "https://api.github.com/users/AngheloAlf/events{/privacy}",
                "followers_url": "https://api.github.com/users/AngheloAlf/followers",
                "following_url": "https://api.github.com/users/AngheloAlf/following{/other_user}",
                "gists_url": "https://api.github.com/users/AngheloAlf/gists{/gist_id}",
                "gravatar_id": "",
                "html_url": "https://github.com/AngheloAlf",
                "id": 7416381,
                "login": "AngheloAlf",
                "organizations_url": "https://api.github.com/users/AngheloAlf/orgs",
                "received_events_url": "https://api.github.com/users/AngheloAlf/received_events",
                "repos_url": "https://api.github.com/users/AngheloAlf/repos",
                "site_admin": false,
                "starred_url": "https://api.github.com/users/AngheloAlf/starred{/owner}{/repo}",
                "subscriptions_url": "https://api.github.com/users/AngheloAlf/subscriptions",
                "type": "User",
                "url": "https://api.github.com/users/AngheloAlf"
            }
        }
    ],
    "comments": 2,
    "comments_url": "https://api.github.com/repos/cython/cython/issues/1922/comments",
    "created_at": "2017-10-10T00:44:53Z",
    "event_data": [],
    "events_url": "https://api.github.com/repos/cython/cython/issues/1922/events",
    "html_url": "https://github.com/cython/cython/issues/1922",
    "id": 264065615,
    "labels": [],
    "labels_url": "https://api.github.com/repos/cython/cython/issues/1922/labels{/name}",
    "locked": false,
    "milestone": null,
    "number": 1922,
    "repository_url": "https://api.github.com/repos/cython/cython",
    "state": "open",
    "title": "Python3 crashing with bytes decodes",
    "updated_at": "2017-10-10T14:14:38Z",
    "url": "https://api.github.com/repos/cython/cython/issues/1922",
    "user": {
        "avatar_url": "https://avatars2.githubusercontent.com/u/7416381?v=4",
        "events_url": "https://api.github.com/users/AngheloAlf/events{/privacy}",
        "followers_url": "https://api.github.com/users/AngheloAlf/followers",
        "following_url": "https://api.github.com/users/AngheloAlf/following{/other_user}",
        "gists_url": "https://api.github.com/users/AngheloAlf/gists{/gist_id}",
        "gravatar_id": "",
        "html_url": "https://github.com/AngheloAlf",
        "id": 7416381,
        "login": "AngheloAlf",
        "organizations_url": "https://api.github.com/users/AngheloAlf/orgs",
        "received_events_url": "https://api.github.com/users/AngheloAlf/received_events",
        "repos_url": "https://api.github.com/users/AngheloAlf/repos",
        "site_admin": false,
        "starred_url": "https://api.github.com/users/AngheloAlf/starred{/owner}{/repo}",
        "subscriptions_url": "https://api.github.com/users/AngheloAlf/subscriptions",
        "type": "User",
        "url": "https://api.github.com/users/AngheloAlf"
    }
}